<sdf version='1.6'>
  <model name='ridgeback'>
    <link name='base_link'>
      <pose frame=''>0 0 0 0 -0 0</pose>
      <inertial>
        <pose frame=''>-0.007355 0.001881 0.066007 0 -0 0</pose>
        <mass>175.572</mass>
        <inertia>
          <ixx>5.03143</ixx>
          <ixy>-0.00270239</ixy>
          <ixz>0.0702784</ixz>
          <iyy>5.56513</iyy>
          <iyz>0.0306834</iyz>
          <izz>8.65405</izz>
        </inertia>
      </inertial>
      <collision name='base_link_fixed_joint_lump__chassis_link_collision'>
        <pose frame=''>0 0 0 0 -0 0</pose>
        <geometry>
          <mesh>
            <scale>1 1 1</scale>
            <uri>model://ridgeback_description/meshes/body-collision.stl</uri>
          </mesh>
        </geometry>
        <surface>
          <contact>
            <ode/>
          </contact>
          <friction>
            <ode/>
          </friction>
        </surface>
      </collision>
      <collision name='base_link_fixed_joint_lump__top_link_collision_1'>
        <pose frame=''>0 0 0 0 -0 0</pose>
        <geometry>
          <mesh>
            <scale>1 1 1</scale>
            <uri>model://ridgeback_description/meshes/top.stl</uri>
          </mesh>
        </geometry>
        <surface>
          <contact>
            <ode/>
          </contact>
          <friction>
            <ode/>
          </friction>
        </surface>
      </collision>
      <visual name='base_link_fixed_joint_lump__chassis_link_visual'>
        <pose frame=''>0 0 0 0 -0 0</pose>
        <geometry>
          <mesh>
            <scale>1 1 1</scale>
            <uri>model://ridgeback_description/meshes/body.stl</uri>
          </mesh>
        </geometry>
        <material>
          <script>
            <name>Gazebo/DarkGrey</name>
            <uri>file://media/materials/scripts/gazebo.material</uri>
          </script>
        </material>
      </visual>
      <visual name='base_link_fixed_joint_lump__axle_link_visual_1'>
        <pose frame=''>0 0 0.05 3.14159 1.57079 3.14159</pose>
        <geometry>
          <mesh>
            <scale>1 1 1</scale>
            <uri>model://ridgeback_description/meshes/axle.stl</uri>
          </mesh>
        </geometry>
        <material>
          <script>
            <name>Gazebo/DarkGrey</name>
            <uri>file://media/materials/scripts/gazebo.material</uri>
          </script>
        </material>
      </visual>
      <visual name='base_link_fixed_joint_lump__rear_rocker_link_visual_2'>
        <pose frame=''>-0.319 0 0.05 1.5708 -0 1.5708</pose>
        <geometry>
          <mesh>
            <scale>1 1 1</scale>
            <uri>model://ridgeback_description/meshes/rocker.stl</uri>
          </mesh>
        </geometry>
        <material>
          <script>
            <name>Gazebo/DarkGrey</name>
            <uri>file://media/materials/scripts/gazebo.material</uri>
          </script>
        </material>
      </visual>
      <visual name='base_link_fixed_joint_lump__front_cover_link_visual_3'>
        <pose frame=''>0 0 0 0 -0 0</pose>
        <geometry>
          <mesh>
            <scale>1 1 1</scale>
            <uri>model://ridgeback_description/meshes/end-cover.stl</uri>
          </mesh>
        </geometry>
        <material>
          <script>
            <name>Gazebo/DarkGrey</name>
            <uri>file://media/materials/scripts/gazebo.material</uri>
          </script>
        </material>
      </visual>
      <visual name='base_link_fixed_joint_lump__front_lights_link_visual_4'>
        <pose frame=''>0 0 0 0 -0 0</pose>
        <geometry>
          <mesh>
            <scale>1 1 1</scale>
            <uri>model://ridgeback_description/meshes/lights.stl</uri>
          </mesh>
        </geometry>
        <material>
          <script>
            <name>Gazebo/White</name>
            <uri>file://media/materials/scripts/gazebo.material</uri>
          </script>
        </material>
      </visual>
      <visual name='base_link_fixed_joint_lump__left_side_cover_link_visual_5'>
        <pose frame=''>0 0 0 0 -0 -3.14159</pose>
        <geometry>
          <mesh>
            <scale>1 1 1</scale>
            <uri>model://ridgeback_description/meshes/side-cover.stl</uri>
          </mesh>
        </geometry>
        <material>
          <script>
            <name>Gazebo/Yellow</name>
            <uri>file://media/materials/scripts/gazebo.material</uri>
          </script>
        </material>
      </visual>
      <visual name='base_link_fixed_joint_lump__rear_cover_link_visual_6'>
        <pose frame=''>0 0 0 0 -0 -3.14159</pose>
        <geometry>
          <mesh>
            <scale>1 1 1</scale>
            <uri>model://ridgeback_description/meshes/end-cover.stl</uri>
          </mesh>
        </geometry>
        <material>
          <script>
            <name>Gazebo/DarkGrey</name>
            <uri>file://media/materials/scripts/gazebo.material</uri>
          </script>
        </material>
      </visual>
      <visual name='base_link_fixed_joint_lump__rear_lights_link_visual_7'>
        <pose frame=''>0 0 0 0 -0 -3.14159</pose>
        <geometry>
          <mesh>
            <scale>1 1 1</scale>
            <uri>model://ridgeback_description/meshes/lights.stl</uri>
          </mesh>
        </geometry>
        <material>
          <script>
            <name>Gazebo/Red</name>
            <uri>file://media/materials/scripts/gazebo.material</uri>
          </script>
        </material>
      </visual>
      <visual name='base_link_fixed_joint_lump__right_side_cover_link_visual_8'>
        <pose frame=''>0 0 0 0 -0 0</pose>
        <geometry>
          <mesh>
            <scale>1 1 1</scale>
            <uri>model://ridgeback_description/meshes/side-cover.stl</uri>
          </mesh>
        </geometry>
        <material>
          <script>
            <name>Gazebo/Yellow</name>
            <uri>file://media/materials/scripts/gazebo.material</uri>
          </script>
        </material>
      </visual>
      <visual name='base_link_fixed_joint_lump__top_link_visual_9'>
        <pose frame=''>0 0 0 0 -0 0</pose>
        <geometry>
          <mesh>
            <scale>1 1 1</scale>
            <uri>model://ridgeback_description/meshes/top.stl</uri>
          </mesh>
        </geometry>
        <material>
          <script>
            <name>Gazebo/DarkGrey</name>
            <uri>file://media/materials/scripts/gazebo.material</uri>
          </script>
        </material>
      </visual>
      <velocity_decay/>
      <velocity_decay/>
      <velocity_decay/>
      <velocity_decay/>
      <velocity_decay/>
      <velocity_decay/>
      <velocity_decay/>
      <velocity_decay/>
      <velocity_decay/>
      <gravity>1</gravity>
      <velocity_decay/>
      <gravity>1</gravity>
      <velocity_decay/>
    </link>
    <link name='front_rocker_link'>
      <pose frame=''>0.319 0 0.05 0 -0 0</pose>
      <inertial>
        <pose frame=''>0 0 0 1.5708 -0 1.5708</pose>
        <mass>10.267</mass>
        <inertia>
          <ixx>0.0288</ixx>
          <ixy>2.20484e-06</ixy>
          <ixz>-1.3145e-05</ixz>
          <iyy>0.4324</iyy>
          <iyz>0.0018944</iyz>
          <izz>0.413</izz>
        </inertia>
      </inertial>
      <visual name='front_rocker_link_visual'>
        <pose frame=''>0 0 0 1.5708 -0 1.5708</pose>
        <geometry>
          <mesh>
            <scale>1 1 1</scale>
            <uri>model://ridgeback_description/meshes/rocker.stl</uri>
          </mesh>
        </geometry>
        <material>
          <script>
            <name>Gazebo/DarkGrey</name>
            <uri>file://media/materials/scripts/gazebo.material</uri>
          </script>
        </material>
      </visual>
      <gravity>1</gravity>
      <velocity_decay/>
    </link>
    <joint name='front_rocker' type='revolute'>
      <child>front_rocker_link</child>
      <parent>base_link</parent>
      <axis>
        <xyz>1 0 0</xyz>
        <limit>
          <lower>-0.08726</lower>
          <upper>0.08726</upper>
          <effort>0</effort>
          <velocity>0</velocity>
        </limit>
        <dynamics>
          <spring_reference>0</spring_reference>
          <spring_stiffness>0</spring_stiffness>
        </dynamics>
        <use_parent_model_frame>1</use_parent_model_frame>
      </axis>
    </joint>
    <link name='front_left_wheel_link'>
      <pose frame=''>0.319 0.2755 0.05 0 -0 0</pose>
      <inertial>
        <pose frame=''>0 0 0 0 -0 0</pose>
        <mass>2.3</mass>
        <inertia>
          <ixx>0.0033212</ixx>
          <ixy>0</ixy>
          <ixz>0</ixz>
          <iyy>0.0066424</iyy>
          <iyz>0</iyz>
          <izz>0.0033212</izz>
        </inertia>
      </inertial>
      <collision name='front_left_wheel_link_collision'>
        <pose frame=''>0 0 0 1.5708 -0 0</pose>
        <geometry>
          <cylinder>
            <length>0.079</length>
            <radius>0.0759</radius>
          </cylinder>
        </geometry>
        <surface>
          <contact>
            <ode/>
          </contact>
          <friction>
            <ode>
              <mu>0</mu>
              <mu2>0</mu2>
            </ode>
          </friction>
        </surface>
      </collision>
      <visual name='front_left_wheel_link_visual'>
        <pose frame=''>0 0 0 1.5708 -0 0</pose>
        <geometry>
          <mesh>
            <scale>1 1 1</scale>
            <uri>model://ridgeback_description/meshes/wheel.stl</uri>
          </mesh>
        </geometry>
        <material>
          <script>
            <name>Gazebo/DarkGrey</name>
            <uri>file://media/materials/scripts/gazebo.material</uri>
          </script>
        </material>
      </visual>
      <gravity>1</gravity>
      <velocity_decay/>
    </link>
    <joint name='front_left_wheel' type='revolute'>
      <child>front_left_wheel_link</child>
      <parent>front_rocker_link</parent>
      <axis>
        <xyz>0 1 0</xyz>
        <limit>
          <lower>-1e+16</lower>
          <upper>1e+16</upper>
        </limit>
        <dynamics>
          <spring_reference>0</spring_reference>
          <spring_stiffness>0</spring_stiffness>
        </dynamics>
        <use_parent_model_frame>1</use_parent_model_frame>
      </axis>
    </joint>
    <link name='front_right_wheel_link'>
      <pose frame=''>0.319 -0.2755 0.05 0 -0 0</pose>
      <inertial>
        <pose frame=''>0 0 0 0 -0 0</pose>
        <mass>2.3</mass>
        <inertia>
          <ixx>0.0033212</ixx>
          <ixy>0</ixy>
          <ixz>0</ixz>
          <iyy>0.0066424</iyy>
          <iyz>0</iyz>
          <izz>0.0033212</izz>
        </inertia>
      </inertial>
      <collision name='front_right_wheel_link_collision'>
        <pose frame=''>0 0 0 1.5708 -0 0</pose>
        <geometry>
          <cylinder>
            <length>0.079</length>
            <radius>0.0759</radius>
          </cylinder>
        </geometry>
        <surface>
          <contact>
            <ode/>
          </contact>
          <friction>
            <ode>
              <mu>0</mu>
              <mu2>0</mu2>
            </ode>
          </friction>
        </surface>
      </collision>
      <visual name='front_right_wheel_link_visual'>
        <pose frame=''>0 0 0 1.5708 -0 0</pose>
        <geometry>
          <mesh>
            <scale>1 1 1</scale>
            <uri>model://ridgeback_description/meshes/wheel.stl</uri>
          </mesh>
        </geometry>
        <material>
          <script>
            <name>Gazebo/DarkGrey</name>
            <uri>file://media/materials/scripts/gazebo.material</uri>
          </script>
        </material>
      </visual>
      <gravity>1</gravity>
      <velocity_decay/>
    </link>
    <joint name='front_right_wheel' type='revolute'>
      <child>front_right_wheel_link</child>
      <parent>front_rocker_link</parent>
      <axis>
        <xyz>0 1 0</xyz>
        <limit>
          <lower>-1e+16</lower>
          <upper>1e+16</upper>
        </limit>
        <dynamics>
          <spring_reference>0</spring_reference>
          <spring_stiffness>0</spring_stiffness>
        </dynamics>
        <use_parent_model_frame>1</use_parent_model_frame>
      </axis>
    </joint>
    <link name='rear_left_wheel_link'>
      <pose frame=''>-0.319 0.2755 0.05 0 -0 0</pose>
      <inertial>
        <pose frame=''>0 0 0 0 -0 0</pose>
        <mass>2.3</mass>
        <inertia>
          <ixx>0.0033212</ixx>
          <ixy>0</ixy>
          <ixz>0</ixz>
          <iyy>0.0066424</iyy>
          <iyz>0</iyz>
          <izz>0.0033212</izz>
        </inertia>
      </inertial>
      <collision name='rear_left_wheel_link_collision'>
        <pose frame=''>0 0 0 1.5708 -0 0</pose>
        <geometry>
          <cylinder>
            <length>0.079</length>
            <radius>0.0759</radius>
          </cylinder>
        </geometry>
        <surface>
          <contact>
            <ode/>
          </contact>
          <friction>
            <ode>
              <mu>0</mu>
              <mu2>0</mu2>
            </ode>
          </friction>
        </surface>
      </collision>
      <visual name='rear_left_wheel_link_visual'>
        <pose frame=''>0 0 0 1.5708 -0 0</pose>
        <geometry>
          <mesh>
            <scale>1 1 1</scale>
            <uri>model://ridgeback_description/meshes/wheel.stl</uri>
          </mesh>
        </geometry>
        <material>
          <script>
            <name>Gazebo/DarkGrey</name>
            <uri>file://media/materials/scripts/gazebo.material</uri>
          </script>
        </material>
      </visual>
      <gravity>1</gravity>
      <velocity_decay/>
    </link>
    <joint name='rear_left_wheel' type='revolute'>
      <child>rear_left_wheel_link</child>
      <parent>base_link</parent>
      <axis>
        <xyz>0 1 0</xyz>
        <limit>
          <lower>-1e+16</lower>
          <upper>1e+16</upper>
        </limit>
        <dynamics>
          <spring_reference>0</spring_reference>
          <spring_stiffness>0</spring_stiffness>
        </dynamics>
        <use_parent_model_frame>1</use_parent_model_frame>
      </axis>
    </joint>
    <link name='rear_right_wheel_link'>
      <pose frame=''>-0.319 -0.2755 0.05 0 -0 0</pose>
      <inertial>
        <pose frame=''>0 0 0 0 -0 0</pose>
        <mass>2.3</mass>
        <inertia>
          <ixx>0.0033212</ixx>
          <ixy>0</ixy>
          <ixz>0</ixz>
          <iyy>0.0066424</iyy>
          <iyz>0</iyz>
          <izz>0.0033212</izz>
        </inertia>
      </inertial>
      <collision name='rear_right_wheel_link_collision'>
        <pose frame=''>0 0 0 1.5708 -0 0</pose>
        <geometry>
          <cylinder>
            <length>0.079</length>
            <radius>0.0759</radius>
          </cylinder>
        </geometry>
        <surface>
          <contact>
            <ode/>
          </contact>
          <friction>
            <ode>
              <mu>0</mu>
              <mu2>0</mu2>
            </ode>
          </friction>
        </surface>
      </collision>
      <visual name='rear_right_wheel_link_visual'>
        <pose frame=''>0 0 0 1.5708 -0 0</pose>
        <geometry>
          <mesh>
            <scale>1 1 1</scale>
            <uri>model://ridgeback_description/meshes/wheel.stl</uri>
          </mesh>
        </geometry>
        <material>
          <script>
            <name>Gazebo/DarkGrey</name>
            <uri>file://media/materials/scripts/gazebo.material</uri>
          </script>
        </material>
      </visual>
      <gravity>1</gravity>
      <velocity_decay/>
    </link>
    <joint name='rear_right_wheel' type='revolute'>
      <child>rear_right_wheel_link</child>
      <parent>base_link</parent>
      <axis>
        <xyz>0 1 0</xyz>
        <limit>
          <lower>-1e+16</lower>
          <upper>1e+16</upper>
        </limit>
        <dynamics>
          <spring_reference>0</spring_reference>
          <spring_stiffness>0</spring_stiffness>
        </dynamics>
        <use_parent_model_frame>1</use_parent_model_frame>
      </axis>
    </joint>
    <plugin name='gazebo_ros_control' filename='libgazebo_ros_control.so'>
      <robotNamespace>/</robotNamespace>
    </plugin>
    <plugin name='ridgeback_ros_force_based_move' filename='libridgeback_ros_force_based_move.so'>
      <robotNamespace>/</robotNamespace>
      <commandTopic>cmd_vel</commandTopic>
      <odometryTopic>odom</odometryTopic>
      <odometryFrame>odom</odometryFrame>
      <odometryRate>25.0</odometryRate>
      <robotBaseFrame>base_link</robotBaseFrame>
      <cmdVelTimeOut>0.25</cmdVelTimeOut>
      <publishOdometryTf>0</publishOdometryTf>
      <yaw_velocity_p_gain>500.0</yaw_velocity_p_gain>
      <x_velocity_p_gain>10000.0</x_velocity_p_gain>
      <y_velocity_p_gain>10000.0</y_velocity_p_gain>
    </plugin>
    <plugin name='imu_controller' filename='libhector_gazebo_ros_imu.so'>
      <robotNamespace>/</robotNamespace>
      <updateRate>50.0</updateRate>
      <topicName>imu/data</topicName>
      <frameId>base_link</frameId>
      <accelDrift>0.005 0.005 0.005</accelDrift>
      <accelGaussianNoise>0.005 0.005 0.005</accelGaussianNoise>
      <rateDrift>0.00005 0.00005 0.00005</rateDrift>
      <rateGaussianNoise>0.00005 0.00005 0.00005</rateGaussianNoise>
      <headingDrift>0.005</headingDrift>
      <headingGaussianNoise>0.005</headingGaussianNoise>
      <bodyName>base_link</bodyName>
      <xyzOffset>-0.2085 0.2902 -0.1681</xyzOffset>
      <rpyOffset>0 -0 0</rpyOffset>
    </plugin>
    <plugin name='gazebo_ros_joint_state_publisher' filename='libgazebo_ros_joint_state_publisher.so'>
      <jointName>front_rocker</jointName>
      <robotNamespace>/</robotNamespace>
      <updateRate>50.0</updateRate>
    </plugin>
    <static>0</static>
    <plugin name='p3d_base_controller' filename='libgazebo_ros_p3d.so'>
      <alwaysOn>1</alwaysOn>
      <updateRate>50.0</updateRate>
      <bodyName>base_link</bodyName>
      <topicName>ground_truth/state</topicName>
      <gaussianNoise>0.01</gaussianNoise>
      <frameName>map</frameName>
      <xyzOffsets>0 0 0</xyzOffsets>
      <rpyOffsets>0 0 0</rpyOffsets>
    </plugin>
  </model>
</sdf>
